INFO:     Will watch for changes in these directories: ['/home/workspace']
INFO:     Uvicorn running on http://0.0.0.0:8000 (Press CTRL+C to quit)
INFO:     Started reloader process [429] using StatReload
INFO:     Started server process [431]
INFO:     Waiting for application startup.
INFO:     Application startup complete.
INFO:     172.20.0.1:43840 - "HEAD / HTTP/1.1" 405 Method Not Allowed
INFO:     172.20.0.1:43850 - "GET /v1/products HTTP/1.1" 200 OK
INFO:     172.20.0.1:43864 - "OPTIONS /v1/products HTTP/1.1" 200 OK
INFO:     172.20.0.1:43850 - "GET /v1/products HTTP/1.1" 200 OK
INFO:     172.20.0.1:43864 - "POST /v1/products HTTP/1.1" 500 Internal Server Error
ERROR:    Exception in ASGI application
Traceback (most recent call last):
  File "/usr/local/lib/python3.13/site-packages/uvicorn/protocols/http/h11_impl.py", line 408, in run_asgi
    result = await app(  # type: ignore[func-returns-value]
             ^^^^^^^^^^^^^^^^^^^^^^^^^^^^^^^^^^^^^^^^^^^^^^
        self.scope, self.receive, self.send
        ^^^^^^^^^^^^^^^^^^^^^^^^^^^^^^^^^^^
    )
    ^
  File "/usr/local/lib/python3.13/site-packages/uvicorn/middleware/proxy_headers.py", line 84, in __call__
    return await self.app(scope, receive, send)
           ^^^^^^^^^^^^^^^^^^^^^^^^^^^^^^^^^^^^
  File "/usr/local/lib/python3.13/site-packages/fastapi/applications.py", line 1106, in __call__
    await super().__call__(scope, receive, send)
  File "/usr/local/lib/python3.13/site-packages/starlette/applications.py", line 122, in __call__
    await self.middleware_stack(scope, receive, send)
  File "/usr/local/lib/python3.13/site-packages/starlette/middleware/errors.py", line 184, in __call__
    raise exc
  File "/usr/local/lib/python3.13/site-packages/starlette/middleware/errors.py", line 162, in __call__
    await self.app(scope, receive, _send)
  File "/usr/local/lib/python3.13/site-packages/starlette/middleware/cors.py", line 91, in __call__
    await self.simple_response(scope, receive, send, request_headers=headers)
  File "/usr/local/lib/python3.13/site-packages/starlette/middleware/cors.py", line 146, in simple_response
    await self.app(scope, receive, send)
  File "/usr/local/lib/python3.13/site-packages/starlette/middleware/exceptions.py", line 79, in __call__
    raise exc
  File "/usr/local/lib/python3.13/site-packages/starlette/middleware/exceptions.py", line 68, in __call__
    await self.app(scope, receive, sender)
  File "/usr/local/lib/python3.13/site-packages/fastapi/middleware/asyncexitstack.py", line 20, in __call__
    raise e
  File "/usr/local/lib/python3.13/site-packages/fastapi/middleware/asyncexitstack.py", line 17, in __call__
    await self.app(scope, receive, send)
  File "/usr/local/lib/python3.13/site-packages/starlette/routing.py", line 718, in __call__
    await route.handle(scope, receive, send)
  File "/usr/local/lib/python3.13/site-packages/starlette/routing.py", line 276, in handle
    await self.app(scope, receive, send)
  File "/usr/local/lib/python3.13/site-packages/starlette/routing.py", line 66, in app
    response = await func(request)
               ^^^^^^^^^^^^^^^^^^^
  File "/usr/local/lib/python3.13/site-packages/fastapi/routing.py", line 274, in app
    raw_response = await run_endpoint_function(
                   ^^^^^^^^^^^^^^^^^^^^^^^^^^^^
        dependant=dependant, values=values, is_coroutine=is_coroutine
        ^^^^^^^^^^^^^^^^^^^^^^^^^^^^^^^^^^^^^^^^^^^^^^^^^^^^^^^^^^^^^
    )
    ^
  File "/usr/local/lib/python3.13/site-packages/fastapi/routing.py", line 193, in run_endpoint_function
    return await run_in_threadpool(dependant.call, **values)
           ^^^^^^^^^^^^^^^^^^^^^^^^^^^^^^^^^^^^^^^^^^^^^^^^^
  File "/usr/local/lib/python3.13/site-packages/starlette/concurrency.py", line 41, in run_in_threadpool
    return await anyio.to_thread.run_sync(func, *args)
           ^^^^^^^^^^^^^^^^^^^^^^^^^^^^^^^^^^^^^^^^^^^
  File "/usr/local/lib/python3.13/site-packages/anyio/to_thread.py", line 33, in run_sync
    return await get_asynclib().run_sync_in_worker_thread(
           ^^^^^^^^^^^^^^^^^^^^^^^^^^^^^^^^^^^^^^^^^^^^^^^
        func, *args, cancellable=cancellable, limiter=limiter
        ^^^^^^^^^^^^^^^^^^^^^^^^^^^^^^^^^^^^^^^^^^^^^^^^^^^^^
    )
    ^
  File "/usr/local/lib/python3.13/site-packages/anyio/_backends/_asyncio.py", line 877, in run_sync_in_worker_thread
    return await future
           ^^^^^^^^^^^^
  File "/usr/local/lib/python3.13/site-packages/anyio/_backends/_asyncio.py", line 807, in run
    result = context.run(func, *args)
  File "/home/workspace/main.py", line 203, in create_product
    product_id = create_document("product", product)
  File "/home/workspace/database.py", line 43, in create_document
    result = db[collection_name].insert_one(data_dict)
  File "/usr/local/lib/python3.13/site-packages/pymongo/collection.py", line 669, in insert_one
    self._insert_one(
    ~~~~~~~~~~~~~~~~^
        document,
        ^^^^^^^^^
    ...<5 lines>...
        comment=comment,
        ^^^^^^^^^^^^^^^^
    ),
    ^
  File "/usr/local/lib/python3.13/site-packages/pymongo/collection.py", line 609, in _insert_one
    self.__database.client._retryable_write(acknowledged, _insert_command, session)
    ~~~~~~~~~~~~~~~~~~~~~~~~~~~~~~~~~~~~~~~^^^^^^^^^^^^^^^^^^^^^^^^^^^^^^^^^^^^^^^^
  File "/usr/local/lib/python3.13/site-packages/pymongo/mongo_client.py", line 1523, in _retryable_write
    return self._retry_with_session(retryable, func, s, bulk)
           ~~~~~~~~~~~~~~~~~~~~~~~~^^^^^^^^^^^^^^^^^^^^^^^^^^
  File "/usr/local/lib/python3.13/site-packages/pymongo/mongo_client.py", line 1421, in _retry_with_session
    return self._retry_internal(
           ~~~~~~~~~~~~~~~~~~~~^
        func=func,
        ^^^^^^^^^^
    ...<2 lines>...
        retryable=retryable,
        ^^^^^^^^^^^^^^^^^^^^
    )
    ^
  File "/usr/local/lib/python3.13/site-packages/pymongo/_csot.py", line 107, in csot_wrapper
    return func(self, *args, **kwargs)
  File "/usr/local/lib/python3.13/site-packages/pymongo/mongo_client.py", line 1462, in _retry_internal
    ).run()
      ~~~^^
  File "/usr/local/lib/python3.13/site-packages/pymongo/mongo_client.py", line 2315, in run
    return self._read() if self._is_read else self._write()
                                              ~~~~~~~~~~~^^
  File "/usr/local/lib/python3.13/site-packages/pymongo/mongo_client.py", line 2422, in _write
    return self._func(self._session, conn, self._retryable)  # type: ignore
           ~~~~~~~~~~^^^^^^^^^^^^^^^^^^^^^^^^^^^^^^^^^^^^^^
  File "/usr/local/lib/python3.13/site-packages/pymongo/collection.py", line 597, in _insert_command
    result = conn.command(
        self.__database.name,
    ...<5 lines>...
        retryable_write=retryable_write,
    )
  File "/usr/local/lib/python3.13/site-packages/pymongo/helpers.py", line 322, in inner
    return func(*args, **kwargs)
  File "/usr/local/lib/python3.13/site-packages/pymongo/pool.py", line 996, in command
    self._raise_connection_failure(error)
    ~~~~~~~~~~~~~~~~~~~~~~~~~~~~~~^^^^^^^
  File "/usr/local/lib/python3.13/site-packages/pymongo/pool.py", line 968, in command
    return command(
        self,
    ...<20 lines>...
        write_concern=write_concern,
    )
  File "/usr/local/lib/python3.13/site-packages/pymongo/network.py", line 151, in command
    request_id, msg, size, max_doc_size = message._op_msg(
                                          ~~~~~~~~~~~~~~~^
        flags, spec, dbname, read_preference, codec_options, ctx=compression_ctx
        ^^^^^^^^^^^^^^^^^^^^^^^^^^^^^^^^^^^^^^^^^^^^^^^^^^^^^^^^^^^^^^^^^^^^^^^^
    )
    ^
  File "/usr/local/lib/python3.13/site-packages/pymongo/message.py", line 762, in _op_msg
    return _op_msg_uncompressed(flags, command, identifier, docs, opts)
bson.errors.InvalidDocument: cannot encode object: HttpUrl('https://example.com/models/visionpro.glb'), of type: <class 'pydantic.networks.HttpUrl'>
INFO:     172.20.0.1:43850 - "POST /v1/products HTTP/1.1" 500 Internal Server Error
ERROR:    Exception in ASGI application
Traceback (most recent call last):
  File "/usr/local/lib/python3.13/site-packages/uvicorn/protocols/http/h11_impl.py", line 408, in run_asgi
    result = await app(  # type: ignore[func-returns-value]
             ^^^^^^^^^^^^^^^^^^^^^^^^^^^^^^^^^^^^^^^^^^^^^^
        self.scope, self.receive, self.send
        ^^^^^^^^^^^^^^^^^^^^^^^^^^^^^^^^^^^
    )
    ^
  File "/usr/local/lib/python3.13/site-packages/uvicorn/middleware/proxy_headers.py", line 84, in __call__
    return await self.app(scope, receive, send)
           ^^^^^^^^^^^^^^^^^^^^^^^^^^^^^^^^^^^^
  File "/usr/local/lib/python3.13/site-packages/fastapi/applications.py", line 1106, in __call__
    await super().__call__(scope, receive, send)
  File "/usr/local/lib/python3.13/site-packages/starlette/applications.py", line 122, in __call__
    await self.middleware_stack(scope, receive, send)
  File "/usr/local/lib/python3.13/site-packages/starlette/middleware/errors.py", line 184, in __call__
    raise exc
  File "/usr/local/lib/python3.13/site-packages/starlette/middleware/errors.py", line 162, in __call__
    await self.app(scope, receive, _send)
  File "/usr/local/lib/python3.13/site-packages/starlette/middleware/cors.py", line 91, in __call__
    await self.simple_response(scope, receive, send, request_headers=headers)
  File "/usr/local/lib/python3.13/site-packages/starlette/middleware/cors.py", line 146, in simple_response
    await self.app(scope, receive, send)
  File "/usr/local/lib/python3.13/site-packages/starlette/middleware/exceptions.py", line 79, in __call__
    raise exc
  File "/usr/local/lib/python3.13/site-packages/starlette/middleware/exceptions.py", line 68, in __call__
    await self.app(scope, receive, sender)
  File "/usr/local/lib/python3.13/site-packages/fastapi/middleware/asyncexitstack.py", line 20, in __call__
    raise e
  File "/usr/local/lib/python3.13/site-packages/fastapi/middleware/asyncexitstack.py", line 17, in __call__
    await self.app(scope, receive, send)
  File "/usr/local/lib/python3.13/site-packages/starlette/routing.py", line 718, in __call__
    await route.handle(scope, receive, send)
  File "/usr/local/lib/python3.13/site-packages/starlette/routing.py", line 276, in handle
    await self.app(scope, receive, send)
  File "/usr/local/lib/python3.13/site-packages/starlette/routing.py", line 66, in app
    response = await func(request)
               ^^^^^^^^^^^^^^^^^^^
  File "/usr/local/lib/python3.13/site-packages/fastapi/routing.py", line 274, in app
    raw_response = await run_endpoint_function(
                   ^^^^^^^^^^^^^^^^^^^^^^^^^^^^
        dependant=dependant, values=values, is_coroutine=is_coroutine
        ^^^^^^^^^^^^^^^^^^^^^^^^^^^^^^^^^^^^^^^^^^^^^^^^^^^^^^^^^^^^^
    )
    ^
  File "/usr/local/lib/python3.13/site-packages/fastapi/routing.py", line 193, in run_endpoint_function
    return await run_in_threadpool(dependant.call, **values)
           ^^^^^^^^^^^^^^^^^^^^^^^^^^^^^^^^^^^^^^^^^^^^^^^^^
  File "/usr/local/lib/python3.13/site-packages/starlette/concurrency.py", line 41, in run_in_threadpool
    return await anyio.to_thread.run_sync(func, *args)
           ^^^^^^^^^^^^^^^^^^^^^^^^^^^^^^^^^^^^^^^^^^^
  File "/usr/local/lib/python3.13/site-packages/anyio/to_thread.py", line 33, in run_sync
    return await get_asynclib().run_sync_in_worker_thread(
           ^^^^^^^^^^^^^^^^^^^^^^^^^^^^^^^^^^^^^^^^^^^^^^^
        func, *args, cancellable=cancellable, limiter=limiter
        ^^^^^^^^^^^^^^^^^^^^^^^^^^^^^^^^^^^^^^^^^^^^^^^^^^^^^
    )
    ^
  File "/usr/local/lib/python3.13/site-packages/anyio/_backends/_asyncio.py", line 877, in run_sync_in_worker_thread
    return await future
           ^^^^^^^^^^^^
  File "/usr/local/lib/python3.13/site-packages/anyio/_backends/_asyncio.py", line 807, in run
    result = context.run(func, *args)
  File "/home/workspace/main.py", line 203, in create_product
    product_id = create_document("product", product)
  File "/home/workspace/database.py", line 43, in create_document
    result = db[collection_name].insert_one(data_dict)
  File "/usr/local/lib/python3.13/site-packages/pymongo/collection.py", line 669, in insert_one
    self._insert_one(
    ~~~~~~~~~~~~~~~~^
        document,
        ^^^^^^^^^
    ...<5 lines>...
        comment=comment,
        ^^^^^^^^^^^^^^^^
    ),
    ^
  File "/usr/local/lib/python3.13/site-packages/pymongo/collection.py", line 609, in _insert_one
    self.__database.client._retryable_write(acknowledged, _insert_command, session)
    ~~~~~~~~~~~~~~~~~~~~~~~~~~~~~~~~~~~~~~~^^^^^^^^^^^^^^^^^^^^^^^^^^^^^^^^^^^^^^^^
  File "/usr/local/lib/python3.13/site-packages/pymongo/mongo_client.py", line 1523, in _retryable_write
    return self._retry_with_session(retryable, func, s, bulk)
           ~~~~~~~~~~~~~~~~~~~~~~~~^^^^^^^^^^^^^^^^^^^^^^^^^^
  File "/usr/local/lib/python3.13/site-packages/pymongo/mongo_client.py", line 1421, in _retry_with_session
    return self._retry_internal(
           ~~~~~~~~~~~~~~~~~~~~^
        func=func,
        ^^^^^^^^^^
    ...<2 lines>...
        retryable=retryable,
        ^^^^^^^^^^^^^^^^^^^^
    )
    ^
  File "/usr/local/lib/python3.13/site-packages/pymongo/_csot.py", line 107, in csot_wrapper
    return func(self, *args, **kwargs)
  File "/usr/local/lib/python3.13/site-packages/pymongo/mongo_client.py", line 1462, in _retry_internal
    ).run()
      ~~~^^
  File "/usr/local/lib/python3.13/site-packages/pymongo/mongo_client.py", line 2315, in run
    return self._read() if self._is_read else self._write()
                                              ~~~~~~~~~~~^^
  File "/usr/local/lib/python3.13/site-packages/pymongo/mongo_client.py", line 2422, in _write
    return self._func(self._session, conn, self._retryable)  # type: ignore
           ~~~~~~~~~~^^^^^^^^^^^^^^^^^^^^^^^^^^^^^^^^^^^^^^
  File "/usr/local/lib/python3.13/site-packages/pymongo/collection.py", line 597, in _insert_command
    result = conn.command(
        self.__database.name,
    ...<5 lines>...
        retryable_write=retryable_write,
    )
  File "/usr/local/lib/python3.13/site-packages/pymongo/helpers.py", line 322, in inner
    return func(*args, **kwargs)
  File "/usr/local/lib/python3.13/site-packages/pymongo/pool.py", line 996, in command
    self._raise_connection_failure(error)
    ~~~~~~~~~~~~~~~~~~~~~~~~~~~~~~^^^^^^^
  File "/usr/local/lib/python3.13/site-packages/pymongo/pool.py", line 968, in command
    return command(
        self,
    ...<20 lines>...
        write_concern=write_concern,
    )
  File "/usr/local/lib/python3.13/site-packages/pymongo/network.py", line 151, in command
    request_id, msg, size, max_doc_size = message._op_msg(
                                          ~~~~~~~~~~~~~~~^
        flags, spec, dbname, read_preference, codec_options, ctx=compression_ctx
        ^^^^^^^^^^^^^^^^^^^^^^^^^^^^^^^^^^^^^^^^^^^^^^^^^^^^^^^^^^^^^^^^^^^^^^^^
    )
    ^
  File "/usr/local/lib/python3.13/site-packages/pymongo/message.py", line 762, in _op_msg
    return _op_msg_uncompressed(flags, command, identifier, docs, opts)
bson.errors.InvalidDocument: cannot encode object: HttpUrl('https://example.com/models/visionpro.glb'), of type: <class 'pydantic.networks.HttpUrl'>
